Workbook

Sheet pomiary
A1: Dla wszystkich | C1: DN [-] | D1: trawa | F1: DN [-] | G1: woda | I1: DN [-] | J1: kostka betonowa | L1: DN [-] | M1: gleba | O1: DN [-] | P1: asfalt | R1: DN [-] | S1: papa | U1: panel refeerncyjny | W1: reflektancja [-] = pomiar / referencja * reflektancja panelu
A2: Dł. Fali [nm] | C2: referencja | D2: pomiar | F2: referencja | G2: pomiar | I2: referencja | J2: pomiar | L2: referencja | M2: pomiar | O2: referencja | P2: pomiar | R2: referencja | S2: pomiar | U2: reflektancja [-] | W2: trawa | X2: woda | Y2: kostka betonowa | Z2: gleba | AA2: asfalt | AB2: papa
A3: 350 | C3: -216.2467 | D3: -239.23098 | F3: -253.03359 | G3: -251.56164 | I3: -242.70183 | J3: -245.11978 | L3: -232.69243 | M3: -231.45681 | O3: -95.84618 | P3: -125.60885 | R3: -140.44746 | S3: -159.46729 | U3: 0.983 | W3: =D3/C3*$U3 -> 1.0874804 | X3: =G3/F3*$U3 -> 0.97728168 | Y3: =J3/I3*$U3 -> 0.99279327 | Z3: =M3/L3*$U3 -> 0.97778017 | AA3: =P3/O3*$U3 -> 1.2882464 | AB3: =S3/R3*$U3 -> 1.1161209
A4: 351 | C4: -216.2467 | D4: -239.23098 | F4: -253.03359 | G4: -251.56164 | I4: -242.70183 | J4: -245.11978 | L4: -232.69243 | M4: -231.45681 | O4: -95.84618 | P4: -125.60885 | R4: -140.44746 | S4: -159.46729 | U4: 0.984 | W4: =D4/C4*$U4 -> 1.0885867 | X4: =G4/F4*$U4 -> 0.97827586 | Y4: =J4/I4*$U4 -> 0.99380323 | Z4: =M4/L4*$U4 -> 0.97877486 | AA4: =P4/O4*$U4 -> 1.289557 | AB4: =S4/R4*$U4 -> 1.1172563
A5: 352 | C5: -216.2467 | D5: -239.23098 | F5: -253.03359 | G5: -251.56164 | I5: -242.70183 | J5: -245.11978 | L5: -232.69243 | M5: -231.45681 | O5: -95.84618 | P5: -125.60885 | R5: -140.44746 | S5: -159.46729 | U5: 0.985 | W5: =D5/C5*$U5 -> 1.089693 | X5: =G5/F5*$U5 -> 0.97927005 | Y5: =J5/I5*$U5 -> 0.9948132 | Z5: =M5/L5*$U5 -> 0.97976955 | AA5: =P5/O5*$U5 -> 1.2908675 | AB5: =S5/R5*$U5 -> 1.1183918
A6: 353 | C6: -216.2467 | D6: -239.23098 | F6: -253.03359 | G6: -251.56164 | I6: -242.70183 | J6: -245.11978 | L6: -232.69243 | M6: -231.45681 | O6: -95.84618 | P6: -125.60885 | R6: -140.44746 | S6: -159.46729 | U6: 0.984 | W6: =D6/C6*$U6 -> 1.0885867 | X6: =G6/F6*$U6 -> 0.97827586 | Y6: =J6/I6*$U6 -> 0.99380323 | Z6: =M6/L6*$U6 -> 0.97877486 | AA6: =P6/O6*$U6 -> 1.289557 | AB6: =S6/R6*$U6 -> 1.1172563
A7: 354 | C7: -216.2467 | D7: -239.23098 | F7: -253.03359 | G7: -251.56164 | I7: -242.70183 | J7: -245.11978 | L7: -232.69243 | M7: -231.45681 | O7: -95.84618 | P7: -125.60885 | R7: -140.44746 | S7: -159.46729 | U7: 0.985 | W7: =D7/C7*$U7 -> 1.089693 | X7: =G7/F7*$U7 -> 0.97927005 | Y7: =J7/I7*$U7 -> 0.9948132 | Z7: =M7/L7*$U7 -> 0.97976955 | AA7: =P7/O7*$U7 -> 1.2908675 | AB7: =S7/R7*$U7 -> 1.1183918
A8: 355 | C8: -216.2467 | D8: -239.23098 | F8: -253.03359 | G8: -251.56164 | I8: -242.70183 | J8: -245.11978 | L8: -232.69243 | M8: -231.45681 | O8: -95.84618 | P8: -125.60885 | R8: -140.44746 | S8: -159.46729 | U8: 0.985 | W8: =D8/C8*$U8 -> 1.089693 | X8: =G8/F8*$U8 -> 0.97927005 | Y8: =J8/I8*$U8 -> 0.9948132 | Z8: =M8/L8*$U8 -> 0.97976955 | AA8: =P8/O8*$U8 -> 1.2908675 | AB8: =S8/R8*$U8 -> 1.1183918
A9: 356 | C9: -216.2467 | D9: -239.23098 | F9: -253.03359 | G9: -251.56164 | I9: -242.70183 | J9: -245.11978 | L9: -232.69243 | M9: -231.45681 | O9: -95.84618 | P9: -125.60885 | R9: -140.44746 | S9: -159.46729 | U9: 0.984 | W9: =D9/C9*$U9 -> 1.0885867 | X9: =G9/F9*$U9 -> 0.97827586 | Y9: =J9/I9*$U9 -> 0.99380323 | Z9: =M9/L9*$U9 -> 0.97877486 | AA9: =P9/O9*$U9 -> 1.289557 | AB9: =S9/R9*$U9 -> 1.1172563
A10: 357 | C10: -216.2467 | D10: -239.23098 | F10: -253.03359 | G10: -251.56164 | I10: -242.70183 | J10: -245.11978 | L10: -232.69243 | M10: -231.45681 | O10: -95.84618 | P10: -125.60885 | R10: -140.44746 | S10: -159.46729 | U10: 0.985 | W10: =D10/C10*$U10 -> 1.089693 | X10: =G10/F10*$U10 -> 0.97927005 | Y10: =J10/I10*$U10 -> 0.9948132 | Z10: =M10/L10*$U10 -> 0.97976955 | AA10: =P10/O10*$U10 -> 1.2908675 | AB10: =S10/R10*$U10 -> 1.1183918
A11: 358 | C11: -216.2467 | D11: -239.23098 | F11: -253.03359 | G11: -251.56164 | I11: -242.70183 | J11: -245.11978 | L11: -232.69243 | M11: -231.45681 | O11: -95.84618 | P11: -125.60885 | R11: -140.44746 | S11: -159.46729 | U11: 0.984 | W11: =D11/C11*$U11 -> 1.0885867 | X11: =G11/F11*$U11 -> 0.97827586 | Y11: =J11/I11*$U11 -> 0.99380323 | Z11: =M11/L11*$U11 -> 0.97877486 | AA11: =P11/O11*$U11 -> 1.289557 | AB11: =S11/R11*$U11 -> 1.1172563
A12: 359 | C12: -216.2467 | D12: -239.23098 | F12: -253.03359 | G12: -251.56164 | I12: -242.70183 | J12: -245.11978 | L12: -232.69243 | M12: -231.45681 | O12: -95.84618 | P12: -125.60885 | R12: -140.44746 | S12: -159.46729 | U12: 0.984 | W12: =D12/C12*$U12 -> 1.0885867 | X12: =G12/F12*$U12 -> 0.97827586 | Y12: =J12/I12*$U12 -> 0.99380323 | Z12: =M12/L12*$U12 -> 0.97877486 | AA12: =P12/O12*$U12 -> 1.289557 | AB12: =S12/R12*$U12 -> 1.1172563
A13: 360 | C13: -216.2467 | D13: -239.23098 | F13: -253.03359 | G13: -251.56164 | I13: -242.70183 | J13: -245.11978 | L13: -232.69243 | M13: -231.45681 | O13: -95.84618 | P13: -125.60885 | R13: -140.44746 | S13: -159.46729 | U13: 0.984 | W13: =D13/C13*$U13 -> 1.0885867 | X13: =G13/F13*$U13 -> 0.97827586 | Y13: =J13/I13*$U13 -> 0.99380323 | Z13: =M13/L13*$U13 -> 0.97877486 | AA13: =P13/O13*$U13 -> 1.289557 | AB13: =S13/R13*$U13 -> 1.1172563
A14: 361 | C14: -216.2467 | D14: -239.23098 | F14: -253.03359 | G14: -251.56164 | I14: -242.70183 | J14: -245.11978 | L14: -232.69243 | M14: -231.45681 | O14: -95.84618 | P14: -125.60885 | R14: -140.44746 | S14: -159.46729 | U14: 0.984 | W14: =D14/C14*$U14 -> 1.0885867 | X14: =G14/F14*$U14 -> 0.97827586 | Y14: =J14/I14*$U14 -> 0.99380323 | Z14: =M14/L14*$U14 -> 0.97877486 | AA14: =P14/O14*$U14 -> 1.289557 | AB14: =S14/R14*$U14 -> 1.1172563
... A753: 1100 | C753: 362.1685 | D753: 176.3313 | F753: 315.3887 | G753: 153.0479 | I753: 332.5909 | J753: 185.82 | L753: 338.6258 | M753: 208.713 | O753: 466.805 | P753: 305.0628 | R753: 424.1824 | S753: 268.6387 | U753: 0.988 | W753: =D753/C753*$U753 -> 0.4810339 | X753: =G753/F753*$U753 -> 0.47944433 | Y753: =J753/I753*$U753 -> 0.55199995 | Z753: =M753/L753*$U753 -> 0.60895668 | AA753: =P753/O753*$U753 -> 0.64567013 | AB753: =S753/R753*$U753 -> 0.62570968
U754: 0.988
U755: 0.988
U756: 0.988
U757: 0.988
U758: 0.988
U759: 0.988
U760: 0.988
U761: 0.988
U762: 0.988
U763: 0.988
U764: 0.988
U765: 0.988
... U2153: 0.935

Sheet SRF kanały WV2
A1: Dł. Fali [nm] | B1: Coastal Blue | C1: Blue | D1: Green | E1: Yellow | F1: Red | G1: RedEdge | H1: NIR1 | I1: NIR2 | P1: Reflektancja przeliczona na kanały WV2: P = suma(p*s) / suma(s)
A2: 350 | B2: 1.9e-06 | C2: 8e-07 | D2: 4e-07 | E2: 3e-07 | F2: 3e-07 | G2: 1e-07 | H2: 3e-07 | I2: 3e-07 | P2: kanał | Q2: centralna dł. fali [nm] | R2: trawa | S2: woda | T2: kostka betonowa | U2: gleba | V2: asfalt | W2: papa
A3: 351 | B3: 1.9e-06 | C3: 8e-07 | D3: 4e-07 | E3: 3e-07 | F3: 3e-07 | G3: 1e-07 | H3: 3e-07 | I3: 3e-07 | P3: coastal blue | Q3: 427 | R3: =SUMPRODUCT(pomiary!W$3:W$753,$B$2:$B$752)/SUM($B$2:$B$752) -> 0.030843743 | S3: =SUMPRODUCT(pomiary!X$3:X$753,$B$2:$B$752)/SUM($B$2:$B$752) -> 0.034515295 | T3: =SUMPRODUCT(pomiary!Y$3:Y$753,$B$2:$B$752)/SUM($B$2:$B$752) -> 0.21691352 | U3: =SUMPRODUCT(pomiary!Z$3:Z$753,$B$2:$B$752)/SUM($B$2:$B$752) -> 0.1290186 | V3: =SUMPRODUCT(pomiary!AA$3:AA$753,$B$2:$B$752)/SUM($B$2:$B$752) -> 0.14729793 | W3: =SUMPRODUCT(pomiary!AB$3:AB$753,$B$2:$B$752)/SUM($B$2:$B$752) -> 0.1409084
A4: 352 | B4: 1.9e-06 | C4: 8e-07 | D4: 4e-07 | E4: 3e-07 | F4: 3e-07 | G4: 1e-07 | H4: 3e-07 | I4: 3e-07 | P4: blue | Q4: 478 | R4: =SUMPRODUCT(pomiary!W$3:W$753,$C$2:$C$752)/SUM($C$2:$C$752) -> 0.02365303 | S4: =SUMPRODUCT(pomiary!X$3:X$753,$C$2:$C$752)/SUM($C$2:$C$752) -> 0.021520147 | T4: =SUMPRODUCT(pomiary!Y$3:Y$753,$C$2:$C$752)/SUM($C$2:$C$752) -> 0.16834931 | U4: =SUMPRODUCT(pomiary!Z$3:Z$753,$C$2:$C$752)/SUM($C$2:$C$752) -> 0.14646216 | V4: =SUMPRODUCT(pomiary!AA$3:AA$753,$C$2:$C$752)/SUM($C$2:$C$752) -> 0.14144146 | W4: =SUMPRODUCT(pomiary!AB$3:AB$753,$C$2:$C$752)/SUM($C$2:$C$752) -> 0.15920806
A5: 353 | B5: 3.3e-06 | C5: 4e-07 | D5: 3e-07 | E5: 1e-07 | F5: 1e-07 | G5: 2e-07 | H5: 0 | I5: 7e-06 | P5: green | Q5: 546 | R5: =SUMPRODUCT(pomiary!W$3:W$753,$D$2:$D$752)/SUM($D$2:$D$752) -> 0.056987657 | S5: =SUMPRODUCT(pomiary!X$3:X$753,$D$2:$D$752)/SUM($D$2:$D$752) -> 0.028197313 | T5: =SUMPRODUCT(pomiary!Y$3:Y$753,$D$2:$D$752)/SUM($D$2:$D$752) -> 0.20235527 | U5: =SUMPRODUCT(pomiary!Z$3:Z$753,$D$2:$D$752)/SUM($D$2:$D$752) -> 0.20169162 | V5: =SUMPRODUCT(pomiary!AA$3:AA$753,$D$2:$D$752)/SUM($D$2:$D$752) -> 0.15680843 | W5: =SUMPRODUCT(pomiary!AB$3:AB$753,$D$2:$D$752)/SUM($D$2:$D$752) -> 0.16984092
A6: 354 | B6: 3.3e-06 | C6: 4e-07 | D6: 3e-07 | E6: 1e-07 | F6: 1e-07 | G6: 2e-07 | H6: 0 | I6: 7e-06 | P6: yellow | Q6: 608 | R6: =SUMPRODUCT(pomiary!W$3:W$753,$E$2:$E$752)/SUM($E$2:$E$752) -> 0.045009509 | S6: =SUMPRODUCT(pomiary!X$3:X$753,$E$2:$E$752)/SUM($E$2:$E$752) -> 0.026446062 | T6: =SUMPRODUCT(pomiary!Y$3:Y$753,$E$2:$E$752)/SUM($E$2:$E$752) -> 0.21721557 | U6: =SUMPRODUCT(pomiary!Z$3:Z$753,$E$2:$E$752)/SUM($E$2:$E$752) -> 0.24195777 | V6: =SUMPRODUCT(pomiary!AA$3:AA$753,$E$2:$E$752)/SUM($E$2:$E$752) -> 0.17414216 | W6: =SUMPRODUCT(pomiary!AB$3:AB$753,$E$2:$E$752)/SUM($E$2:$E$752) -> 0.16590434
A7: 355 | B7: 3.3e-06 | C7: 3e-07 | D7: 1e-07 | E7: 1e-07 | F7: 1e-07 | G7: 3e-07 | H7: 0 | I7: 1.99e-05 | P7: red | Q7: 659 | R7: =SUMPRODUCT(pomiary!W$3:W$753,$F$2:$F$752)/SUM($F$2:$F$752) -> 0.034697184 | S7: =SUMPRODUCT(pomiary!X$3:X$753,$F$2:$F$752)/SUM($F$2:$F$752) -> 0.020561937 | T7: =SUMPRODUCT(pomiary!Y$3:Y$753,$F$2:$F$752)/SUM($F$2:$F$752) -> 0.21466844 | U7: =SUMPRODUCT(pomiary!Z$3:Z$753,$F$2:$F$752)/SUM($F$2:$F$752) -> 0.26242287 | V7: =SUMPRODUCT(pomiary!AA$3:AA$753,$F$2:$F$752)/SUM($F$2:$F$752) -> 0.18437737 | W7: =SUMPRODUCT(pomiary!AB$3:AB$753,$F$2:$F$752)/SUM($F$2:$F$752) -> 0.16096765
A8: 356 | B8: 3.3e-06 | C8: 3e-07 | D8: 1e-07 | E8: 1e-07 | F8: 1e-07 | G8: 3e-07 | H8: 0 | I8: 1.99e-05 | P8: red edge | Q8: 724 | R8: =SUMPRODUCT(pomiary!W$3:W$753,$G$2:$G$752)/SUM($G$2:$G$752) -> 0.25446409 | S8: =SUMPRODUCT(pomiary!X$3:X$753,$G$2:$G$752)/SUM($G$2:$G$752) -> 0.018185041 | T8: =SUMPRODUCT(pomiary!Y$3:Y$753,$G$2:$G$752)/SUM($G$2:$G$752) -> 0.23229533 | U8: =SUMPRODUCT(pomiary!Z$3:Z$753,$G$2:$G$752)/SUM($G$2:$G$752) -> 0.29353787 | V8: =SUMPRODUCT(pomiary!AA$3:AA$753,$G$2:$G$752)/SUM($G$2:$G$752) -> 0.20576666 | W8: =SUMPRODUCT(pomiary!AB$3:AB$753,$G$2:$G$752)/SUM($G$2:$G$752) -> 0.16056102
A9: 357 | B9: 3.3e-06 | C9: 3e-07 | D9: 1e-07 | E9: 1e-07 | F9: 1e-07 | G9: 3e-07 | H9: 0 | I9: 1.99e-05 | P9: NIR1 | Q9: 831 | R9: =SUMPRODUCT(pomiary!W$3:W$753,$H$2:$H$752)/SUM($H$2:$H$752) -> 0.45319511 | S9: =SUMPRODUCT(pomiary!X$3:X$753,$H$2:$H$752)/SUM($H$2:$H$752) -> 0.027490176 | T9: =SUMPRODUCT(pomiary!Y$3:Y$753,$H$2:$H$752)/SUM($H$2:$H$752) -> 0.24279072 | U9: =SUMPRODUCT(pomiary!Z$3:Z$753,$H$2:$H$752)/SUM($H$2:$H$752) -> 0.33194265 | V9: =SUMPRODUCT(pomiary!AA$3:AA$753,$H$2:$H$752)/SUM($H$2:$H$752) -> 0.24205585 | W9: =SUMPRODUCT(pomiary!AB$3:AB$753,$H$2:$H$752)/SUM($H$2:$H$752) -> 0.18480268
A10: 358 | B10: 2.8e-06 | C10: 2e-07 | D10: 2e-07 | E10: 1e-07 | F10: 0 | G10: 2e-07 | H10: 1e-07 | I10: 8.74e-05 | P10: NIR2 | Q10: 908 | R10: =SUMPRODUCT(pomiary!W$3:W$753,$I$2:$I$752)/SUM($I$2:$I$752) -> 0.45887614 | S10: =SUMPRODUCT(pomiary!X$3:X$753,$I$2:$I$752)/SUM($I$2:$I$752) -> 0.10319258 | T10: =SUMPRODUCT(pomiary!Y$3:Y$753,$I$2:$I$752)/SUM($I$2:$I$752) -> 0.29133232 | U10: =SUMPRODUCT(pomiary!Z$3:Z$753,$I$2:$I$752)/SUM($I$2:$I$752) -> 0.38478185 | V10: =SUMPRODUCT(pomiary!AA$3:AA$753,$I$2:$I$752)/SUM($I$2:$I$752) -> 0.32973321 | W10: =SUMPRODUCT(pomiary!AB$3:AB$753,$I$2:$I$752)/SUM($I$2:$I$752) -> 0.275242
A11: 359 | B11: 2.8e-06 | C11: 2e-07 | D11: 2e-07 | E11: 1e-07 | F11: 0 | G11: 2e-07 | H11: 1e-07 | I11: 8.74e-05 | P11: centralne dł. fali - Tabela 1 z instrukcji
A12: 360 | B12: 1.7e-06 | C12: 3e-07 | D12: 2e-07 | E12: 0 | F12: 1e-07 | G12: 2e-07 | H12: 1e-07 | I12: 7.48e-05
A13: 361 | B13: 1.7e-06 | C13: 3e-07 | D13: 2e-07 | E13: 0 | F13: 1e-07 | G13: 2e-07 | H13: 1e-07 | I13: 7.48e-05
A14: 362 | B14: 1.7e-06 | C14: 3e-07 | D14: 2e-07 | E14: 0 | F14: 1e-07 | G14: 2e-07 | H14: 1e-07 | I14: 7.48e-05 | P14: Reflektancja ze zdjęcia zjdecieSatelitarne.tif (Identify Features)
A15: 363 | B15: 3.3e-06 | C15: 1e-07 | D15: 1e-07 | E15: 0 | F15: 0 | G15: 1e-07 | H15: 0 | I15: 5.2e-06 | P15: kanał | Q15: centralna dł. fali [nm] | R15: trawa | S15: woda | T15: kostka betonowa | U15: gleba | V15: asfalt | W15: papa
A16: 364 | B16: 3.3e-06 | C16: 1e-07 | D16: 1e-07 | E16: 0 | F16: 0 | G16: 1e-07 | H16: 0 | I16: 5.2e-06 | P16: coastal blue | Q16: =Q3 -> 427 | R16: 0.12 | S16: 0.1191 | T16: 0.177 | U16: 0.1411 | V16: 0.1542 | W16: 0.1605
A17: 365 | B17: 3.6e-06 | C17: 2e-07 | D17: 2e-07 | E17: 1e-07 | F17: 1e-07 | G17: 1e-07 | H17: 0 | I17: 5e-07 | P17: blue | Q17: =Q4 -> 478 | R17: 0.0956 | S17: 0.0924 | T17: 0.1723 | U17: 0.1251 | V17: 0.1409 | W17: 0.1516
A18: 366 | B18: 3.6e-06 | C18: 2e-07 | D18: 2e-07 | E18: 1e-07 | F18: 1e-07 | G18: 1e-07 | H18: 0 | I18: 5e-07 | P18: green | Q18: =Q5 -> 546 | R18: 0.0917 | S18: 0.0688 | T18: 0.1711 | U18: 0.1138 | V18: 0.119 | W18: 0.1393
A19: 367 | B19: 3.6e-06 | C19: 2e-07 | D19: 2e-07 | E19: 1e-07 | F19: 1e-07 | G19: 1e-07 | H19: 0 | I19: 5e-07 | P19: yellow | Q19: =Q6 -> 608 | R19: 0.062 | S19: 0.0505 | T19: 0.1759 | U19: 0.1166 | V19: 0.1146 | W19: 0.14
A20: 368 | B20: 4.4e-06 | C20: 3e-07 | D20: 2e-07 | E20: 1e-07 | F20: 1e-07 | G20: 2e-07 | H20: 1e-07 | I20: 6e-07 | P20: red | Q20: =Q7 -> 659 | R20: 0.0475 | S20: 0.0415 | T20: 0.1794 | U20: 0.1375 | V20: 0.1109 | W20: 0.1384
A21: 369 | B21: 4.4e-06 | C21: 3e-07 | D21: 2e-07 | E21: 1e-07 | F21: 1e-07 | G21: 2e-07 | H21: 1e-07 | I21: 6e-07 | P21: red edge | Q21: =Q8 -> 724 | R21: 0.2413 | S21: 0.0372 | T21: 0.1866 | U21: 0.1811 | V21: 0.1312 | W21: 0.1409
A22: 370 | B22: 2.9e-06 | C22: 4e-07 | D22: 3e-07 | E22: 1e-07 | F22: 2e-07 | G22: 2e-07 | H22: 1e-07 | I22: 3e-07 | P22: NIR1 | Q22: =Q9 -> 831 | R22: 0.4466 | S22: 0.0341 | T22: 0.2047 | U22: 0.2607 | V22: 0.1457 | W22: 0.1597
A23: 371 | B23: 2.9e-06 | C23: 4e-07 | D23: 3e-07 | E23: 1e-07 | F23: 2e-07 | G23: 2e-07 | H23: 1e-07 | I23: 3e-07 | P23: NIR2 | Q23: =Q10 -> 908 | R23: 0.3646 | S23: 0.0219 | T23: 0.163 | U23: 0.2514 | V23: 0.1132 | W23: 0.1311
A24: 372 | B24: 2.9e-06 | C24: 4e-07 | D24: 3e-07 | E24: 1e-07 | F24: 2e-07 | G24: 2e-07 | H24: 1e-07 | I24: 3e-07 | P24: współrzędne punktu | R24: X=646983.1 | S24: X=647113.2 | T24: X=647123.2 | U24: X=647183.2 | V24: X=646853.1 | W24: X=647269.2
A25: 373 | B25: 6.2e-06 | C25: 5e-07 | D25: 3e-07 | E25: 1e-07 | F25: 1e-07 | G25: 2e-07 | H25: 0 | I25: 1e-07 | P25: (UTM 34N) | R25: Y=5887709.6 | S25: Y=5887329.7 | T25: Y=5887713.6 | U25: Y=5887359.7 | V25: Y=5887825.6 | W25: Y=5887519.7
A26: 374 | B26: 6.2e-06 | C26: 5e-07 | D26: 3e-07 | E26: 1e-07 | F26: 1e-07 | G26: 2e-07 | H26: 0 | I26: 1e-07
A27: 375 | B27: 5.4e-06 | C27: 4e-07 | D27: 2e-07 | E27: 1e-07 | F27: 1e-07 | G27: 2e-07 | H27: 0 | I27: 2e-07
A28: 376 | B28: 5.4e-06 | C28: 4e-07 | D28: 2e-07 | E28: 1e-07 | F28: 1e-07 | G28: 2e-07 | H28: 0 | I28: 2e-07
A29: 377 | B29: 5.4e-06 | C29: 4e-07 | D29: 2e-07 | E29: 1e-07 | F29: 1e-07 | G29: 2e-07 | H29: 0 | I29: 2e-07
A30: 378 | B30: 5e-06 | C30: 5e-07 | D30: 3e-07 | E30: 1e-07 | F30: 2e-07 | G30: 2e-07 | H30: 0 | I30: 3e-07
A31: 379 | B31: 5e-06 | C31: 5e-07 | D31: 3e-07 | E31: 1e-07 | F31: 2e-07 | G31: 2e-07 | H31: 0 | I31: 3e-07
A32: 380 | B32: 7.4e-06 | C32: 4e-07 | D32: 4e-07 | E32: 1e-07 | F32: 2e-07 | G32: 3e-07 | H32: 0 | I32: 1e-07
A33: 381 | B33: 7.4e-06 | C33: 4e-07 | D33: 4e-07 | E33: 1e-07 | F33: 2e-07 | G33: 3e-07 | H33: 0 | I33: 1e-07
A34: 382 | B34: 7.4e-06 | C34: 4e-07 | D34: 4e-07 | E34: 1e-07 | F34: 2e-07 | G34: 3e-07 | H34: 0 | I34: 1e-07
A35: 383 | B35: 1.35e-05 | C35: 3e-07 | D35: 2e-07 | E35: 1e-07 | F35: 1e-07 | G35: 3e-07 | H35: 0 | I35: 2e-07
A36: 384 | B36: 1.35e-05 | C36: 3e-07 | D36: 2e-07 | E36: 1e-07 | F36: 1e-07 | G36: 3e-07 | H36: 0 | I36: 2e-07
A37: 385 | B37: 4.54e-05 | C37: 5e-07 | D37: 4e-07 | E37: 1e-07 | F37: 2e-07 | G37: 3e-07 | H37: 0 | I37: 2e-07
... A752: 1100 | B752: 8.1e-06 | C752: 3.3e-06 | D752: 0.0001401 | E752: 6e-07 | F752: 1e-07 | G752: 5e-07 | H752: 1e-07 | I752: 7e-07

Sheet ECOSTRESS
A1: Dane z biblioteki ECOSTRESS (pliki .txt), przeliczone: nm = um*1000, reflektancja [-] = % / 100
A2: trawa | F2: woda | K2: kostka betonowa | P2: gleba | U2: asfalt | Z2: papa
A3: dł. fali [um] | B3: refl. [%] | C3: dł. fali [nm] | D3: refl. [-] | F3: dł. fali [um] | G3: refl. [%] | H3: dł. fali [nm] | I3: refl. [-] | K3: dł. fali [um] | L3: refl. [%] | M3: dł. fali [nm] | N3: refl. [-] | P3: dł. fali [um] | Q3: refl. [%] | R3: dł. fali [nm] | S3: refl. [-] | U3: dł. fali [um] | V3: refl. [%] | W3: dł. fali [nm] | X3: refl. [-] | Z3: dł. fali [um] | AA3: refl. [%] | AB3: dł. fali [nm] | AC3: refl. [-]
A4: 0.35 | B4: 3.3818 | C4: =A4*1000 -> 350 | D4: =B4/100 -> 0.033818 | F4: 0.4 | G4: 2.7427 | H4: =F4*1000 -> 400 | I4: =G4/100 -> 0.027427 | K4: 0.42 | L4: 29.1167 | M4: =K4*1000 -> 420 | N4: =L4/100 -> 0.291167 | P4: 0.4 | Q4: 2.902 | R4: =P4*1000 -> 400 | S4: =Q4/100 -> 0.02902 | U4: 0.35 | V4: 6.29 | W4: =U4*1000 -> 350 | X4: =V4/100 -> 0.0629 | Z4: 0.35 | AA4: 2.18 | AB4: =Z4*1000 -> 350 | AC4: =AA4/100 -> 0.0218
A5: 0.352 | B5: 3.3994 | C5: =A5*1000 -> 352 | D5: =B5/100 -> 0.033994 | F5: 0.401 | G5: 2.7427 | H5: =F5*1000 -> 401 | I5: =G5/100 -> 0.027427 | K5: 0.422 | L5: 28.3869 | M5: =K5*1000 -> 422 | N5: =L5/100 -> 0.283869 | P5: 0.401 | Q5: 3.1628 | R5: =P5*1000 -> 401 | S5: =Q5/100 -> 0.031628 | U5: 0.352 | V5: 6.31 | W5: =U5*1000 -> 352 | X5: =V5/100 -> 0.0631 | Z5: 0.352 | AA5: 2.19 | AB5: =Z5*1000 -> 352 | AC5: =AA5/100 -> 0.0219
A6: 0.354 | B6: 3.4171 | C6: =A6*1000 -> 354 | D6: =B6/100 -> 0.034171 | F6: 0.402 | G6: 2.7435 | H6: =F6*1000 -> 402 | I6: =G6/100 -> 0.027435 | K6: 0.424 | L6: 28.5691 | M6: =K6*1000 -> 424 | N6: =L6/100 -> 0.285691 | P6: 0.402 | Q6: 3.2727 | R6: =P6*1000 -> 402 | S6: =Q6/100 -> 0.032727 | U6: 0.354 | V6: 6.32 | W6: =U6*1000 -> 354 | X6: =V6/100 -> 0.0632 | Z6: 0.354 | AA6: 2.19 | AB6: =Z6*1000 -> 354 | AC6: =AA6/100 -> 0.0219
A7: 0.356 | B7: 3.4347 | C7: =A7*1000 -> 356 | D7: =B7/100 -> 0.034347 | F7: 0.403 | G7: 2.7442 | H7: =F7*1000 -> 403 | I7: =G7/100 -> 0.027442 | K7: 0.426 | L7: 28.5713 | M7: =K7*1000 -> 426 | N7: =L7/100 -> 0.285713 | P7: 0.403 | Q7: 3.2619 | R7: =P7*1000 -> 403 | S7: =Q7/100 -> 0.032619 | U7: 0.356 | V7: 6.33 | W7: =U7*1000 -> 356 | X7: =V7/100 -> 0.0633 | Z7: 0.356 | AA7: 2.19 | AB7: =Z7*1000 -> 356 | AC7: =AA7/100 -> 0.0219
A8: 0.358 | B8: 3.4524 | C8: =A8*1000 -> 358 | D8: =B8/100 -> 0.034524 | F8: 0.404 | G8: 2.6453 | H8: =F8*1000 -> 404 | I8: =G8/100 -> 0.026453 | K8: 0.428 | L8: 28.7773 | M8: =K8*1000 -> 428 | N8: =L8/100 -> 0.287773 | P8: 0.404 | Q8: 3.2445 | R8: =P8*1000 -> 404 | S8: =Q8/100 -> 0.032445 | U8: 0.358 | V8: 6.34 | W8: =U8*1000 -> 358 | X8: =V8/100 -> 0.0634 | Z8: 0.358 | AA8: 2.19 | AB8: =Z8*1000 -> 358 | AC8: =AA8/100 -> 0.0219
A9: 0.36 | B9: 3.47 | C9: =A9*1000 -> 360 | D9: =B9/100 -> 0.0347 | F9: 0.405 | G9: 2.7396 | H9: =F9*1000 -> 405 | I9: =G9/100 -> 0.027396 | K9: 0.43 | L9: 28.7803 | M9: =K9*1000 -> 430 | N9: =L9/100 -> 0.287803 | P9: 0.405 | Q9: 3.3412 | R9: =P9*1000 -> 405 | S9: =Q9/100 -> 0.033412 | U9: 0.36 | V9: 6.35 | W9: =U9*1000 -> 360 | X9: =V9/100 -> 0.0635 | Z9: 0.36 | AA9: 2.19 | AB9: =Z9*1000 -> 360 | AC9: =AA9/100 -> 0.0219
A10: 0.362 | B10: 3.4876 | C10: =A10*1000 -> 362 | D10: =B10/100 -> 0.034876 | F10: 0.406 | G10: 2.7409 | H10: =F10*1000 -> 406 | I10: =G10/100 -> 0.027409 | K10: 0.432 | L10: 28.9063 | M10: =K10*1000 -> 432 | N10: =L10/100 -> 0.289063 | P10: 0.406 | Q10: 3.3919 | R10: =P10*1000 -> 406 | S10: =Q10/100 -> 0.033919 | U10: 0.362 | V10: 6.37 | W10: =U10*1000 -> 362 | X10: =V10/100 -> 0.0637 | Z10: 0.362 | AA10: 2.2 | AB10: =Z10*1000 -> 362 | AC10: =AA10/100 -> 0.022
A11: 0.364 | B11: 3.5053 | C11: =A11*1000 -> 364 | D11: =B11/100 -> 0.035053 | F11: 0.407 | G11: 2.7404 | H11: =F11*1000 -> 407 | I11: =G11/100 -> 0.027404 | K11: 0.434 | L11: 28.9849 | M11: =K11*1000 -> 434 | N11: =L11/100 -> 0.289849 | P11: 0.407 | Q11: 3.4011 | R11: =P11*1000 -> 407 | S11: =Q11/100 -> 0.034011 | U11: 0.364 | V11: 6.38 | W11: =U11*1000 -> 364 | X11: =V11/100 -> 0.0638 | Z11: 0.364 | AA11: 2.2 | AB11: =Z11*1000 -> 364 | AC11: =AA11/100 -> 0.022
A12: 0.366 | B12: 3.5229 | C12: =A12*1000 -> 366 | D12: =B12/100 -> 0.035229 | F12: 0.408 | G12: 2.7416 | H12: =F12*1000 -> 408 | I12: =G12/100 -> 0.027416 | K12: 0.436 | L12: 29.0834 | M12: =K12*1000 -> 436 | N12: =L12/100 -> 0.290834 | P12: 0.408 | Q12: 3.4937 | R12: =P12*1000 -> 408 | S12: =Q12/100 -> 0.034937 | U12: 0.366 | V12: 6.39 | W12: =U12*1000 -> 366 | X12: =V12/100 -> 0.0639 | Z12: 0.366 | AA12: 2.2 | AB12: =Z12*1000 -> 366 | AC12: =AA12/100 -> 0.022
A13: 0.368 | B13: 3.5406 | C13: =A13*1000 -> 368 | D13: =B13/100 -> 0.035406 | F13: 0.409 | G13: 2.9159 | H13: =F13*1000 -> 409 | I13: =G13/100 -> 0.029159 | K13: 0.438 | L13: 29.185 | M13: =K13*1000 -> 438 | N13: =L13/100 -> 0.29185 | P13: 0.409 | Q13: 3.8165 | R13: =P13*1000 -> 409 | S13: =Q13/100 -> 0.038165 | U13: 0.368 | V13: 6.41 | W13: =U13*1000 -> 368 | X13: =V13/100 -> 0.0641 | Z13: 0.368 | AA13: 2.2 | AB13: =Z13*1000 -> 368 | AC13: =AA13/100 -> 0.022
A14: 0.37 | B14: 3.5582 | C14: =A14*1000 -> 370 | D14: =B14/100 -> 0.035582 | F14: 0.41 | G14: 2.9159 | H14: =F14*1000 -> 410 | I14: =G14/100 -> 0.029159 | K14: 0.44 | L14: 29.2105 | M14: =K14*1000 -> 440 | N14: =L14/100 -> 0.292105 | P14: 0.41 | Q14: 3.5685 | R14: =P14*1000 -> 410 | S14: =Q14/100 -> 0.035685 | U14: 0.37 | V14: 6.43 | W14: =U14*1000 -> 370 | X14: =V14/100 -> 0.0643 | Z14: 0.37 | AA14: 2.21 | AB14: =Z14*1000 -> 370 | AC14: =AA14/100 -> 0.0221
A15: 0.372 | B15: 3.5759 | C15: =A15*1000 -> 372 | D15: =B15/100 -> 0.035759 | F15: 0.411 | G15: 2.8224 | H15: =F15*1000 -> 411 | I15: =G15/100 -> 0.028224 | K15: 0.442 | L15: 29.3204 | M15: =K15*1000 -> 442 | N15: =L15/100 -> 0.293204 | P15: 0.411 | Q15: 3.4548 | R15: =P15*1000 -> 411 | S15: =Q15/100 -> 0.034548 | U15: 0.372 | V15: 6.44 | W15: =U15*1000 -> 372 | X15: =V15/100 -> 0.0644 | Z15: 0.372 | AA15: 2.21 | AB15: =Z15*1000 -> 372 | AC15: =AA15/100 -> 0.0221
... A279: 1.8 | B279: 27.65 | C279: =A279*1000 -> 1800 | D279: =B279/100 -> 0.2765 | F279: 0.675 | G279: 2.776 | H279: =F279*1000 -> 675 | I279: =G279/100 -> 0.02776 | K279: 2.5 | L279: 22.5263 | M279: =K279*1000 -> 2500 | N279: =L279/100 -> 0.225263 | P279: 0.675 | Q279: 29.943 | R279: =P279*1000 -> 675 | S279: =Q279/100 -> 0.29943 | U279: 1.8 | V279: 8.31 | W279: =U279*1000 -> 1800 | X279: =V279/100 -> 0.0831 | Z279: 1.8 | AA279: 3.46 | AB279: =Z279*1000 -> 1800 | AC279: =AA279/100 -> 0.0346
A280: 1.82 | B280: 27.127 | C280: =A280*1000 -> 1820 | D280: =B280/100 -> 0.27127 | F280: 0.676 | G280: 2.693 | H280: =F280*1000 -> 676 | I280: =G280/100 -> 0.02693 | P280: 0.676 | Q280: 29.702 | R280: =P280*1000 -> 676 | S280: =Q280/100 -> 0.29702 | U280: 1.82 | V280: 8.31 | W280: =U280*1000 -> 1820 | X280: =V280/100 -> 0.0831 | Z280: 1.82 | AA280: 3.46 | AB280: =Z280*1000 -> 1820 | AC280: =AA280/100 -> 0.0346
A281: 1.84 | B281: 25.853 | C281: =A281*1000 -> 1840 | D281: =B281/100 -> 0.25853 | F281: 0.677 | G281: 2.683 | H281: =F281*1000 -> 677 | I281: =G281/100 -> 0.02683 | P281: 0.677 | Q281: 29.976 | R281: =P281*1000 -> 677 | S281: =Q281/100 -> 0.29976 | U281: 1.84 | V281: 8.29 | W281: =U281*1000 -> 1840 | X281: =V281/100 -> 0.0829 | Z281: 1.84 | AA281: 3.46 | AB281: =Z281*1000 -> 1840 | AC281: =AA281/100 -> 0.0346
A282: 1.86 | B282: 21.605 | C282: =A282*1000 -> 1860 | D282: =B282/100 -> 0.21605 | F282: 0.678 | G282: 2.687 | H282: =F282*1000 -> 678 | I282: =G282/100 -> 0.02687 | P282: 0.678 | Q282: 29.937 | R282: =P282*1000 -> 678 | S282: =Q282/100 -> 0.29937 | U282: 1.86 | V282: 8.28 | W282: =U282*1000 -> 1860 | X282: =V282/100 -> 0.0828 | Z282: 1.86 | AA282: 3.43 | AB282: =Z282*1000 -> 1860 | AC282: =AA282/100 -> 0.0343
A283: 1.88 | B283: 13.258 | C283: =A283*1000 -> 1880 | D283: =B283/100 -> 0.13258 | F283: 0.679 | G283: 2.687 | H283: =F283*1000 -> 679 | I283: =G283/100 -> 0.02687 | P283: 0.679 | Q283: 30.214 | R283: =P283*1000 -> 679 | S283: =Q283/100 -> 0.30214 | U283: 1.88 | V283: 8.28 | W283: =U283*1000 -> 1880 | X283: =V283/100 -> 0.0828 | Z283: 1.88 | AA283: 3.46 | AB283: =Z283*1000 -> 1880 | AC283: =AA283/100 -> 0.0346
A284: 1.9 | B284: 7.2879 | C284: =A284*1000 -> 1900 | D284: =B284/100 -> 0.072879 | F284: 0.68 | G284: 2.679 | H284: =F284*1000 -> 680 | I284: =G284/100 -> 0.02679 | P284: 0.68 | Q284: 29.862 | R284: =P284*1000 -> 680 | S284: =Q284/100 -> 0.29862 | U284: 1.9 | V284: 8.22 | W284: =U284*1000 -> 1900 | X284: =V284/100 -> 0.0822 | Z284: 1.9 | AA284: 3.45 | AB284: =Z284*1000 -> 1900 | AC284: =AA284/100 -> 0.0345
A285: 1.92 | B285: 5.1658 | C285: =A285*1000 -> 1920 | D285: =B285/100 -> 0.051658 | F285: 0.681 | G285: 2.689 | H285: =F285*1000 -> 681 | I285: =G285/100 -> 0.02689 | P285: 0.681 | Q285: 29.933 | R285: =P285*1000 -> 681 | S285: =Q285/100 -> 0.29933 | U285: 1.92 | V285: 8.17 | W285: =U285*1000 -> 1920 | X285: =V285/100 -> 0.0817 | Z285: 1.92 | AA285: 3.41 | AB285: =Z285*1000 -> 1920 | AC285: =AA285/100 -> 0.0341
A286: 1.94 | B286: 5.0554 | C286: =A286*1000 -> 1940 | D286: =B286/100 -> 0.050554 | F286: 0.682 | G286: 2.4311 | H286: =F286*1000 -> 682 | I286: =G286/100 -> 0.024311 | P286: 0.682 | Q286: 30.071 | R286: =P286*1000 -> 682 | S286: =Q286/100 -> 0.30071 | U286: 1.94 | V286: 8.13 | W286: =U286*1000 -> 1940 | X286: =V286/100 -> 0.0813 | Z286: 1.94 | AA286: 3.43 | AB286: =Z286*1000 -> 1940 | AC286: =AA286/100 -> 0.0343
A287: 1.96 | B287: 5.5539 | C287: =A287*1000 -> 1960 | D287: =B287/100 -> 0.055539 | F287: 0.683 | G287: 2.689 | H287: =F287*1000 -> 683 | I287: =G287/100 -> 0.02689 | P287: 0.683 | Q287: 30.107 | R287: =P287*1000 -> 683 | S287: =Q287/100 -> 0.30107 | U287: 1.96 | V287: 8.15 | W287: =U287*1000 -> 1960 | X287: =V287/100 -> 0.0815 | Z287: 1.96 | AA287: 3.46 | AB287: =Z287*1000 -> 1960 | AC287: =AA287/100 -> 0.0346
A288: 1.98 | B288: 6.5224 | C288: =A288*1000 -> 1980 | D288: =B288/100 -> 0.065224 | F288: 0.684 | G288: 2.689 | H288: =F288*1000 -> 684 | I288: =G288/100 -> 0.02689 | P288: 0.684 | Q288: 30.451 | R288: =P288*1000 -> 684 | S288: =Q288/100 -> 0.30451 | U288: 1.98 | V288: 8.14 | W288: =U288*1000 -> 1980 | X288: =V288/100 -> 0.0814 | Z288: 1.98 | AA288: 3.47 | AB288: =Z288*1000 -> 1980 | AC288: =AA288/100 -> 0.0347
A289: 2 | B289: 7.3972 | C289: =A289*1000 -> 2000 | D289: =B289/100 -> 0.073972 | F289: 0.685 | G289: 2.679 | H289: =F289*1000 -> 685 | I289: =G289/100 -> 0.02679 | P289: 0.685 | Q289: 30.415 | R289: =P289*1000 -> 685 | S289: =Q289/100 -> 0.30415 | U289: 2 | V289: 8.19 | W289: =U289*1000 -> 2000 | X289: =V289/100 -> 0.0819 | Z289: 2 | AA289: 3.47 | AB289: =Z289*1000 -> 2000 | AC289: =AA289/100 -> 0.0347
A290: 2.02 | B290: 8.7469 | C290: =A290*1000 -> 2020 | D290: =B290/100 -> 0.087469 | F290: 0.686 | G290: 2.685 | H290: =F290*1000 -> 686 | I290: =G290/100 -> 0.02685 | P290: 0.686 | Q290: 30.412 | R290: =P290*1000 -> 686 | S290: =Q290/100 -> 0.30412 | U290: 2.02 | V290: 8.23 | W290: =U290*1000 -> 2020 | X290: =V290/100 -> 0.0823 | Z290: 2.02 | AA290: 3.48 | AB290: =Z290*1000 -> 2020 | AC290: =AA290/100 -> 0.0348
A291: 2.04 | B291: 9.7152 | C291: =A291*1000 -> 2040 | D291: =B291/100 -> 0.097152 | F291: 0.687 | G291: 2.679 | H291: =F291*1000 -> 687 | I291: =G291/100 -> 0.02679 | P291: 0.687 | Q291: 30.376 | R291: =P291*1000 -> 687 | S291: =Q291/100 -> 0.30376 | U291: 2.04 | V291: 8.23 | W291: =U291*1000 -> 2040 | X291: =V291/100 -> 0.0823 | Z291: 2.04 | AA291: 3.48 | AB291: =Z291*1000 -> 2040 | AC291: =AA291/100 -> 0.0348
... A314: 2.5 | B314: 6.2297 | C314: =A314*1000 -> 2500 | D314: =B314/100 -> 0.062297 | F314: 0.71 | G314: 2.7429 | H314: =F314*1000 -> 710 | I314: =G314/100 -> 0.027429 | P314: 0.71 | Q314: 31.832 | R314: =P314*1000 -> 710 | S314: =Q314/100 -> 0.31832 | U314: 2.5 | V314: 6.968 | W314: =U314*1000 -> 2500 | X314: =V314/100 -> 0.06968 | Z314: 2.5 | AA314: 3.6371 | AB314: =Z314*1000 -> 2500 | AC314: =AA314/100 -> 0.036371
F315: 0.711 | G315: 2.5792 | H315: =F315*1000 -> 711 | I315: =G315/100 -> 0.025792 | P315: 0.711 | Q315: 32.034 | R315: =P315*1000 -> 711 | S315: =Q315/100 -> 0.32034
F316: 0.712 | G316: 2.5757 | H316: =F316*1000 -> 712 | I316: =G316/100 -> 0.025757 | P316: 0.712 | Q316: 31.685 | R316: =P316*1000 -> 712 | S316: =Q316/100 -> 0.31685
F317: 0.713 | G317: 2.7579 | H317: =F317*1000 -> 713 | I317: =G317/100 -> 0.027579 | P317: 0.713 | Q317: 31.832 | R317: =P317*1000 -> 713 | S317: =Q317/100 -> 0.31832
F318: 0.714 | G318: 2.7636 | H318: =F318*1000 -> 714 | I318: =G318/100 -> 0.027636 | P318: 0.714 | Q318: 32.081 | R318: =P318*1000 -> 714 | S318: =Q318/100 -> 0.32081
F319: 0.715 | G319: 2.7449 | H319: =F319*1000 -> 715 | I319: =G319/100 -> 0.027449 | P319: 0.715 | Q319: 32.285 | R319: =P319*1000 -> 715 | S319: =Q319/100 -> 0.32285
F320: 0.716 | G320: 2.5723 | H320: =F320*1000 -> 716 | I320: =G320/100 -> 0.025723 | P320: 0.716 | Q320: 32.386 | R320: =P320*1000 -> 716 | S320: =Q320/100 -> 0.32386
F321: 0.717 | G321: 2.5671 | H321: =F321*1000 -> 717 | I321: =G321/100 -> 0.025671 | P321: 0.717 | Q321: 32.514 | R321: =P321*1000 -> 717 | S321: =Q321/100 -> 0.32514
F322: 0.718 | G322: 2.5671 | H322: =F322*1000 -> 718 | I322: =G322/100 -> 0.025671 | P322: 0.718 | Q322: 32.252 | R322: =P322*1000 -> 718 | S322: =Q322/100 -> 0.32252
F323: 0.719 | G323: 2.5705 | H323: =F323*1000 -> 719 | I323: =G323/100 -> 0.025705 | P323: 0.719 | Q323: 32.178 | R323: =P323*1000 -> 719 | S323: =Q323/100 -> 0.32178
F324: 0.72 | G324: 2.4833 | H324: =F324*1000 -> 720 | I324: =G324/100 -> 0.024833 | P324: 0.72 | Q324: 31.75 | R324: =P324*1000 -> 720 | S324: =Q324/100 -> 0.3175
F325: 0.721 | G325: 2.634 | H325: =F325*1000 -> 721 | I325: =G325/100 -> 0.02634 | P325: 0.721 | Q325: 31.849 | R325: =P325*1000 -> 721 | S325: =Q325/100 -> 0.31849
...
